Workbook

Sheet crosscheck
A1: id | B1: string in principles (compact) | C1: string in EPUB metadata | D1: EPUB string equals to principles? | E1: string in ONIX | F1: ONIX string equals to principles?
A2: {=_xlfn.UNIQUE(_xlfn.VSTACK('guidelines-string'!$E$2:$E$191,'epub-metadata-strings'!$D$2:$D$82,'onix-metadata-strings'!$D$2:$D$79))} -> ways-of-reading-title | B2: =IFERROR(VLOOKUP($A2&"-compact",'guidelines-string'!$A$2:$G$1000,7,FALSE),"") -> Ways of reading | C2: =IFERROR(VLOOKUP($A2,'epub-metadata-strings'!$D$2:$E$978,2,FALSE),"") -> Ways of reading | D2: =IF($B2="","",EXACT($B2,C2)) -> TRUE | E2: =IFERROR(VLOOKUP($A2,'onix-metadata-strings'!$D$2:$E$982,2,FALSE),"") -> Ways of reading | F2: =IF($B2="","",EXACT($B2,E2)) -> TRUE
A3: ways-of-reading-visual-adjustments-modifiable | B3: =IFERROR(VLOOKUP($A3&"-compact",'guidelines-string'!$A$2:$G$1000,7,FALSE),"") -> Appearance can be modified | C3: =IFERROR(VLOOKUP($A3,'epub-metadata-strings'!$D$2:$E$978,2,FALSE),"") -> Appearance can be modified | D3: =IF($B3="","",EXACT($B3,C3)) -> TRUE | E3: =IFERROR(VLOOKUP($A3,'onix-metadata-strings'!$D$2:$E$982,2,FALSE),"") -> Appearance can be modified | F3: =IF($B3="","",EXACT($B3,E3)) -> TRUE
A4: ways-of-reading-visual-adjustments-unmodifiable | B4: =IFERROR(VLOOKUP($A4&"-compact",'guidelines-string'!$A$2:$G$1000,7,FALSE),"") -> Appearance cannot be modified | C4: =IFERROR(VLOOKUP($A4,'epub-metadata-strings'!$D$2:$E$978,2,FALSE),"") -> Appearance cannot be modified | D4: =IF($B4="","",EXACT($B4,C4)) -> TRUE | E4: =IFERROR(VLOOKUP($A4,'onix-metadata-strings'!$D$2:$E$982,2,FALSE),"") -> Appearance cannot be modified | F4: =IF($B4="","",EXACT($B4,E4)) -> TRUE
A5: ways-of-reading-visual-adjustments-unknown | B5: =IFERROR(VLOOKUP($A5&"-compact",'guidelines-string'!$A$2:$G$1000,7,FALSE),"") -> No information about appearance modifiability is available | C5: =IFERROR(VLOOKUP($A5,'epub-metadata-strings'!$D$2:$E$978,2,FALSE),"") -> No information about appearance modifiability is available | D5: =IF($B5="","",EXACT($B5,C5)) -> TRUE | E5: =IFERROR(VLOOKUP($A5,'onix-metadata-strings'!$D$2:$E$982,2,FALSE),"") -> No information about appearance modifiability is available | F5: =IF($B5="","",EXACT($B5,E5)) -> TRUE
A6: ways-of-reading-nonvisual-reading-readable | B6: =IFERROR(VLOOKUP($A6&"-compact",'guidelines-string'!$A$2:$G$1000,7,FALSE),"") -> Readable in read aloud or dynamic braille | C6: =IFERROR(VLOOKUP($A6,'epub-metadata-strings'!$D$2:$E$978,2,FALSE),"") -> Readable in read aloud or dynamic braille | D6: =IF($B6="","",EXACT($B6,C6)) -> TRUE | E6: =IFERROR(VLOOKUP($A6,'onix-metadata-strings'!$D$2:$E$982,2,FALSE),"") -> Readable in read aloud or dynamic braille | F6: =IF($B6="","",EXACT($B6,E6)) -> TRUE
A7: ways-of-reading-nonvisual-reading-not-fully | B7: =IFERROR(VLOOKUP($A7&"-compact",'guidelines-string'!$A$2:$G$1000,7,FALSE),"") -> Not fully readable in read aloud or dynamic braille | C7: =IFERROR(VLOOKUP($A7,'epub-metadata-strings'!$D$2:$E$978,2,FALSE),"") -> Not fully readable in read aloud or dynamic braille | D7: =IF($B7="","",EXACT($B7,C7)) -> TRUE | E7: =IFERROR(VLOOKUP($A7,'onix-metadata-strings'!$D$2:$E$982,2,FALSE),"") -> Not fully readable in read aloud or dynamic braille | F7: =IF($B7="","",EXACT($B7,E7)) -> TRUE
A8: ways-of-reading-nonvisual-reading-none | B8: =IFERROR(VLOOKUP($A8&"-compact",'guidelines-string'!$A$2:$G$1000,7,FALSE),"") -> Not readable in read aloud or dynamic braille | C8: =IFERROR(VLOOKUP($A8,'epub-metadata-strings'!$D$2:$E$978,2,FALSE),"") -> Not readable in read aloud or dynamic braille | D8: =IF($B8="","",EXACT($B8,C8)) -> TRUE | E8: =IFERROR(VLOOKUP($A8,'onix-metadata-strings'!$D$2:$E$982,2,FALSE),"") -> Not readable in read aloud or dynamic braille | F8: =IF($B8="","",EXACT($B8,E8)) -> TRUE
A9: ways-of-reading-nonvisual-reading-no-metadata | B9: =IFERROR(VLOOKUP($A9&"-compact",'guidelines-string'!$A$2:$G$1000,7,FALSE),"") -> No information about nonvisual reading is available | C9: =IFERROR(VLOOKUP($A9,'epub-metadata-strings'!$D$2:$E$978,2,FALSE),"") -> No information about nonvisual reading is available | D9: =IF($B9="","",EXACT($B9,C9)) -> TRUE | E9: =IFERROR(VLOOKUP($A9,'onix-metadata-strings'!$D$2:$E$982,2,FALSE),"") -> No information about nonvisual reading is available | F9: =IF($B9="","",EXACT($B9,E9)) -> TRUE
A10: ways-of-reading-nonvisual-reading-alt-text | B10: =IFERROR(VLOOKUP($A10&"-compact",'guidelines-string'!$A$2:$G$1000,7,FALSE),"") -> Has alternative text | C10: =IFERROR(VLOOKUP($A10,'epub-metadata-strings'!$D$2:$E$978,2,FALSE),"") -> Has alternative text | D10: =IF($B10="","",EXACT($B10,C10)) -> TRUE | E10: =IFERROR(VLOOKUP($A10,'onix-metadata-strings'!$D$2:$E$982,2,FALSE),"") -> Has alternative text | F10: =IF($B10="","",EXACT($B10,E10)) -> TRUE
A11: ways-of-reading-prerecorded-audio-no-metadata | B11: =IFERROR(VLOOKUP($A11&"-compact",'guidelines-string'!$A$2:$G$1000,7,FALSE),"") -> No information about prerecorded audio is available | C11: =IFERROR(VLOOKUP($A11,'epub-metadata-strings'!$D$2:$E$978,2,FALSE),"") -> No information about prerecorded audio is available | D11: =IF($B11="","",EXACT($B11,C11)) -> TRUE | E11: =IFERROR(VLOOKUP($A11,'onix-metadata-strings'!$D$2:$E$982,2,FALSE),"") -> No information about prerecorded audio is available | F11: =IF($B11="","",EXACT($B11,E11)) -> TRUE
A12: ways-of-reading-prerecorded-audio-only | B12: =IFERROR(VLOOKUP($A12&"-compact",'guidelines-string'!$A$2:$G$1000,7,FALSE),"") -> Prerecorded audio only | C12: =IFERROR(VLOOKUP($A12,'epub-metadata-strings'!$D$2:$E$978,2,FALSE),"") -> Prerecorded audio only | D12: =IF($B12="","",EXACT($B12,C12)) -> TRUE | E12: =IFERROR(VLOOKUP($A12,'onix-metadata-strings'!$D$2:$E$982,2,FALSE),"") -> Prerecorded audio only | F12: =IF($B12="","",EXACT($B12,E12)) -> TRUE
A13: ways-of-reading-prerecorded-audio-synchronized | B13: =IFERROR(VLOOKUP($A13&"-compact",'guidelines-string'!$A$2:$G$1000,7,FALSE),"") -> Prerecorded audio synchronized with text | C13: =IFERROR(VLOOKUP($A13,'epub-metadata-strings'!$D$2:$E$978,2,FALSE),"") -> Prerecorded audio synchronized with text | D13: =IF($B13="","",EXACT($B13,C13)) -> TRUE | E13: =IFERROR(VLOOKUP($A13,'onix-metadata-strings'!$D$2:$E$982,2,FALSE),"") -> Prerecorded audio synchronized with text | F13: =IF($B13="","",EXACT($B13,E13)) -> TRUE
A14: ways-of-reading-prerecorded-audio-complementary | B14: =IFERROR(VLOOKUP($A14&"-compact",'guidelines-string'!$A$2:$G$1000,7,FALSE),"") -> Prerecorded audio clips | C14: =IFERROR(VLOOKUP($A14,'epub-metadata-strings'!$D$2:$E$978,2,FALSE),"") -> Prerecorded audio clips | D14: =IF($B14="","",EXACT($B14,C14)) -> TRUE | E14: =IFERROR(VLOOKUP($A14,'onix-metadata-strings'!$D$2:$E$982,2,FALSE),"") -> Prerecorded audio clips | F14: =IF($B14="","",EXACT($B14,E14)) -> TRUE
... A85: additional-accessibility-information-color-not-sole-means-of-conveying-information | B85: =IFERROR(VLOOKUP($A85&"-compact",'guidelines-string'!$A$2:$G$1000,7,FALSE),"") | C85: =IFERROR(VLOOKUP($A85,'epub-metadata-strings'!$D$2:$E$978,2,FALSE),"") | D85: =IF($B85="","",EXACT($B85,C85)) | E85: =IFERROR(VLOOKUP($A85,'onix-metadata-strings'!$D$2:$E$982,2,FALSE),"") -> Color is not the sole means of conveying information | F85: =IF($B85="","",EXACT($B85,E85))
A86: additional-accessibility-information-dyslexia-readability | B86: =IFERROR(VLOOKUP($A86&"-compact",'guidelines-string'!$A$2:$G$1000,7,FALSE),"") | C86: =IFERROR(VLOOKUP($A86,'epub-metadata-strings'!$D$2:$E$978,2,FALSE),"") | E86: =IFERROR(VLOOKUP($A86,'onix-metadata-strings'!$D$2:$E$982,2,FALSE),"") -> Dyslexia readability
A87: additional-accessibility-information-ultra-high-contrast-between-text-and-background | B87: =IFERROR(VLOOKUP($A87&"-compact",'guidelines-string'!$A$2:$G$1000,7,FALSE),"") | C87: =IFERROR(VLOOKUP($A87,'epub-metadata-strings'!$D$2:$E$978,2,FALSE),"") | E87: =IFERROR(VLOOKUP($A87,'onix-metadata-strings'!$D$2:$E$982,2,FALSE),"") -> Ultra high contrast between text and background
A88: additional-accessibility-information-visible-page-numbering | B88: =IFERROR(VLOOKUP($A88&"-compact",'guidelines-string'!$A$2:$G$1000,7,FALSE),"") | C88: =IFERROR(VLOOKUP($A88,'epub-metadata-strings'!$D$2:$E$978,2,FALSE),"") | E88: =IFERROR(VLOOKUP($A88,'onix-metadata-strings'!$D$2:$E$982,2,FALSE),"") -> Visible page numbering
A89: additional-accessibility-information-without-background-sounds | B89: =IFERROR(VLOOKUP($A89&"-compact",'guidelines-string'!$A$2:$G$1000,7,FALSE),"") | C89: =IFERROR(VLOOKUP($A89,'epub-metadata-strings'!$D$2:$E$978,2,FALSE),"") | E89: =IFERROR(VLOOKUP($A89,'onix-metadata-strings'!$D$2:$E$982,2,FALSE),"") -> Without background sounds
B90: =IFERROR(VLOOKUP($A90&"-compact",'guidelines-string'!$A$2:$G$1000,7,FALSE),"") | C90: =IFERROR(VLOOKUP($A90,'epub-metadata-strings'!$D$2:$E$978,2,FALSE),"") | E90: =IFERROR(VLOOKUP($A90,'onix-metadata-strings'!$D$2:$E$982,2,FALSE),"")
B91: =IFERROR(VLOOKUP($A91&"-compact",'guidelines-string'!$A$2:$G$1000,7,FALSE),"") | C91: =IFERROR(VLOOKUP($A91,'epub-metadata-strings'!$D$2:$E$978,2,FALSE),"") | E91: =IFERROR(VLOOKUP($A91,'onix-metadata-strings'!$D$2:$E$982,2,FALSE),"")
B92: =IFERROR(VLOOKUP($A92&"-compact",'guidelines-string'!$A$2:$G$1000,7,FALSE),"") | C92: =IFERROR(VLOOKUP($A92,'epub-metadata-strings'!$D$2:$E$978,2,FALSE),"") | E92: =IFERROR(VLOOKUP($A92,'onix-metadata-strings'!$D$2:$E$982,2,FALSE),"")
B93: =IFERROR(VLOOKUP($A93&"-compact",'guidelines-string'!$A$2:$G$1000,7,FALSE),"") | C93: =IFERROR(VLOOKUP($A93,'epub-metadata-strings'!$D$2:$E$978,2,FALSE),"") | E93: =IFERROR(VLOOKUP($A93,'onix-metadata-strings'!$D$2:$E$982,2,FALSE),"")
E94: =IFERROR(VLOOKUP($A94,'onix-metadata-strings'!$D$2:$E$982,2,FALSE),"")

Sheet guidelines-string
A1: key | B1: /strings | C1: /strings[xmlns:xhtml] | D1: /strings/string | E1: /strings/string/id | F1: /strings/string/mode | G1: /strings/string/value
A2: =E2&"-"&IF(ISBLANK(F2),"compact",F2) -> ways-of-reading-title-compact | C2: http://www.w3.org/1999/xhtml | E2: ways-of-reading-title | G2: Ways of reading
A3: =E3&"-"&IF(ISBLANK(F3),"compact",F3) -> ways-of-reading-title-compact | E3: ways-of-reading-title | G3: Ways of reading
A4: =E4&"-"&IF(ISBLANK(F4),"compact",F4) -> ways-of-reading-visual-adjustments-modifiable-compact | E4: ways-of-reading-visual-adjustments-modifiable | F4: compact | G4: Appearance can be modified
A5: =E5&"-"&IF(ISBLANK(F5),"compact",F5) -> ways-of-reading-visual-adjustments-modifiable-descriptive | E5: ways-of-reading-visual-adjustments-modifiable | F5: descriptive | G5: Appearance of the text and page layout can be modified according to the capabilities of the reading system (font family and font size, spaces between paragraphs, sentences, words, and letters, as well as color of background and text)
A6: =E6&"-"&IF(ISBLANK(F6),"compact",F6) -> ways-of-reading-visual-adjustments-unmodifiable-compact | E6: ways-of-reading-visual-adjustments-unmodifiable | F6: compact | G6: Appearance cannot be modified
A7: =E7&"-"&IF(ISBLANK(F7),"compact",F7) -> ways-of-reading-visual-adjustments-unmodifiable-descriptive | E7: ways-of-reading-visual-adjustments-unmodifiable | F7: descriptive | G7: Text and page layout cannot be modified as the reading experience is close to a print version, but reading systems can still provide zooming options
A8: =E8&"-"&IF(ISBLANK(F8),"compact",F8) -> ways-of-reading-visual-adjustments-unknown-compact | E8: ways-of-reading-visual-adjustments-unknown | F8: compact | G8: No information about appearance modifiability is available
A9: =E9&"-"&IF(ISBLANK(F9),"compact",F9) -> ways-of-reading-visual-adjustments-unknown-descriptive | E9: ways-of-reading-visual-adjustments-unknown | F9: descriptive | G9: No information about appearance modifiability is available
A10: =E10&"-"&IF(ISBLANK(F10),"compact",F10) -> ways-of-reading-nonvisual-reading-readable-compact | E10: ways-of-reading-nonvisual-reading-readable | F10: compact | G10: Readable in read aloud or dynamic braille
A11: =E11&"-"&IF(ISBLANK(F11),"compact",F11) -> ways-of-reading-nonvisual-reading-readable-descriptive | E11: ways-of-reading-nonvisual-reading-readable | F11: descriptive | G11: All content can be read as read aloud speech or dynamic braille
A12: =E12&"-"&IF(ISBLANK(F12),"compact",F12) -> ways-of-reading-nonvisual-reading-not-fully-compact | E12: ways-of-reading-nonvisual-reading-not-fully | F12: compact | G12: Not fully readable in read aloud or dynamic braille
A13: =E13&"-"&IF(ISBLANK(F13),"compact",F13) -> ways-of-reading-nonvisual-reading-not-fully-descriptive | E13: ways-of-reading-nonvisual-reading-not-fully | F13: descriptive | G13: Not all of the content will be readable as read aloud speech or dynamic braille
A14: =E14&"-"&IF(ISBLANK(F14),"compact",F14) -> ways-of-reading-nonvisual-reading-none-compact | E14: ways-of-reading-nonvisual-reading-none | F14: compact | G14: Not readable in read aloud or dynamic braille
A15: =E15&"-"&IF(ISBLANK(F15),"compact",F15) -> ways-of-reading-nonvisual-reading-none-descriptive | E15: ways-of-reading-nonvisual-reading-none | F15: descriptive | G15: The content is not readable as read aloud speech or dynamic braille
... A28: =E28&"-"&IF(ISBLANK(F28),"compact",F28) -> ways-of-reading-prerecorded-audio-no-metadata-descriptive | E28: ways-of-reading-prerecorded-audio-no-metadata | F28: descriptive | G28: No information about prerecorded audio is available
A29: =E29&"-"&IF(ISBLANK(F29),"compact",F29) -> ways-of-reading-title-compact | E29: ways-of-reading-title | G29: Ways of reading
A30: =E30&"-"&IF(ISBLANK(F30),"compact",F30) -> ways-of-reading-visual-adjustments-modifiable-compact | E30: ways-of-reading-visual-adjustments-modifiable | F30: compact | G30: Appearance can be modified
A31: =E31&"-"&IF(ISBLANK(F31),"compact",F31) -> ways-of-reading-nonvisual-reading-readable-compact | E31: ways-of-reading-nonvisual-reading-readable | F31: compact | G31: Readable in read aloud or dynamic braille
A32: =E32&"-"&IF(ISBLANK(F32),"compact",F32) -> ways-of-reading-nonvisual-reading-alt-text-compact | E32: ways-of-reading-nonvisual-reading-alt-text | F32: compact | G32: Has alternative text
A33: =E33&"-"&IF(ISBLANK(F33),"compact",F33) -> ways-of-reading-title-compact | E33: ways-of-reading-title | G33: Ways of reading
A34: =E34&"-"&IF(ISBLANK(F34),"compact",F34) -> ways-of-reading-visual-adjustments-modifiable-descriptive | E34: ways-of-reading-visual-adjustments-modifiable | F34: descriptive | G34: Appearance of the text and page layout can be modified according to the capabilities of the reading system (font family and font size, spaces between paragraphs, sentences, words, and letters, as well as color of background and text)
A35: =E35&"-"&IF(ISBLANK(F35),"compact",F35) -> ways-of-reading-nonvisual-reading-readable-descriptive | E35: ways-of-reading-nonvisual-reading-readable | F35: descriptive | G35: All content can be read as read aloud speech or dynamic braille
A36: =E36&"-"&IF(ISBLANK(F36),"compact",F36) -> ways-of-reading-nonvisual-reading-alt-text-descriptive | E36: ways-of-reading-nonvisual-reading-alt-text | F36: descriptive | G36: Has alternative text descriptions for images
A37: =E37&"-"&IF(ISBLANK(F37),"compact",F37) -> ways-of-reading-title-compact | E37: ways-of-reading-title | G37: Ways of reading
A38: =E38&"-"&IF(ISBLANK(F38),"compact",F38) -> ways-of-reading-visual-adjustments-modifiable-compact | E38: ways-of-reading-visual-adjustments-modifiable | F38: compact | G38: Appearance can be modified
A39: =E39&"-"&IF(ISBLANK(F39),"compact",F39) -> ways-of-reading-nonvisual-reading-readable-compact | E39: ways-of-reading-nonvisual-reading-readable | F39: compact | G39: Readable in read aloud or dynamic braille
A40: =E40&"-"&IF(ISBLANK(F40),"compact",F40) -> ways-of-reading-prerecorded-audio-synchronized-compact | E40: ways-of-reading-prerecorded-audio-synchronized | F40: compact | G40: Prerecorded audio synchronized with text
A41: =E41&"-"&IF(ISBLANK(F41),"compact",F41) -> ways-of-reading-nonvisual-reading-alt-text-compact | E41: ways-of-reading-nonvisual-reading-alt-text | F41: compact | G41: Has alternative text
A42: =E42&"-"&IF(ISBLANK(F42),"compact",F42) -> ways-of-reading-title-compact | E42: ways-of-reading-title | G42: Ways of reading
A43: =E43&"-"&IF(ISBLANK(F43),"compact",F43) -> ways-of-reading-visual-adjustments-modifiable-descriptive | E43: ways-of-reading-visual-adjustments-modifiable | F43: descriptive | G43: Appearance of the text and page layout can be modified according to the capabilities of the reading system (font family and font size, spaces between paragraphs, sentences, words, and letters, as well as color of background and text)
A44: =E44&"-"&IF(ISBLANK(F44),"compact",F44) -> ways-of-reading-nonvisual-reading-readable-descriptive | E44: ways-of-reading-nonvisual-reading-readable | F44: descriptive | G44: All content can be read as read aloud speech or dynamic braille
A45: =E45&"-"&IF(ISBLANK(F45),"compact",F45) -> ways-of-reading-prerecorded-audio-synchronized-descriptive | E45: ways-of-reading-prerecorded-audio-synchronized | F45: descriptive | G45: All the content is available as prerecorded audio synchronized with text
A46: =E46&"-"&IF(ISBLANK(F46),"compact",F46) -> ways-of-reading-nonvisual-reading-alt-text-descriptive | E46: ways-of-reading-nonvisual-reading-alt-text | F46: descriptive | G46: Has alternative text descriptions for images
A47: =E47&"-"&IF(ISBLANK(F47),"compact",F47) -> conformance-title-compact | E47: conformance-title | G47: Conformance
A48: =E48&"-"&IF(ISBLANK(F48),"compact",F48) -> conformance-a-compact | E48: conformance-a | F48: compact | G48: This publication meets minimum accessibility standards
A49: =E49&"-"&IF(ISBLANK(F49),"compact",F49) -> conformance-a-descriptive | E49: conformance-a | F49: descriptive | G49: The publication contains a conformance statement that it meets the EPUB Accessibility and WCAG 2 Level A standard
A50: =E50&"-"&IF(ISBLANK(F50),"compact",F50) -> conformance-aa-compact | E50: conformance-aa | F50: compact | G50: This publication meets accepted accessibility standards
A51: =E51&"-"&IF(ISBLANK(F51),"compact",F51) -> conformance-aa-descriptive | E51: conformance-aa | F51: descriptive | G51: The publication contains a conformance statement that it meets the EPUB Accessibility and WCAG 2 Level AA standard
A52: =E52&"-"&IF(ISBLANK(F52),"compact",F52) -> conformance-aaa-compact | E52: conformance-aaa | F52: compact | G52: This publication exceeds accepted accessibility standards
...

Sheet epub-metadata-strings
A1: /strings | B1: /strings[xmlns:xhtml] | C1: /strings/string | D1: /strings/string/id | E1: /strings/string/value
B2: http://www.w3.org/1999/xhtml | D2: ways-of-reading-title | E2: Ways of reading
D3: conformance-title | E3: Conformance
D4: navigation-title | E4: Navigation
D5: rich-content-title | E5: Rich content
D6: hazards-title | E6: Hazards
D7: accessibility-summary-title | E7: Accessibility summary
D8: legal-considerations-title | E8: Legal considerations
D9: additional-accessibility-information-title | E9: Additional accessibility information
D10: ways-of-reading-visual-adjustments-modifiable | E10: Appearance can be modified
D11: ways-of-reading-visual-adjustments-unmodifiable | E11: Appearance cannot be modified
D12: ways-of-reading-visual-adjustments-unknown | E12: No information about appearance modifiability is available
D13: ways-of-reading-nonvisual-reading-readable | E13: Readable in read aloud or dynamic braille
D14: ways-of-reading-nonvisual-reading-not-fully | E14: Not fully readable in read aloud or dynamic braille
... D82: additional-accessibility-information-text-to-speech-hinting | E82: Text-to-speech hinting provided

Sheet onix-metadata-strings
A1: /strings | B1: /strings[xmlns:xhtml] | C1: /strings/string | D1: /strings/string/id | E1: /strings/string/value
B2: http://www.w3.org/1999/xhtml | D2: ways-of-reading-title | E2: Ways of reading
D3: conformance-title | E3: Conformance
D4: navigation-title | E4: Navigation
D5: rich-content-title | E5: Rich content
D6: hazards-title | E6: Hazards
D7: accessibility-summary-title | E7: Accessibility summary
D8: legal-considerations-title | E8: Legal considerations
D9: additional-accessibility-information-title | E9: Additional accessibility information
D10: ways-of-reading-visual-adjustments-modifiable | E10: Appearance can be modified
D11: ways-of-reading-visual-adjustments-unmodifiable | E11: Appearance cannot be modified
D12: ways-of-reading-visual-adjustments-unknown | E12: No information about appearance modifiability is available
D13: ways-of-reading-nonvisual-reading-readable | E13: Readable in read aloud or dynamic braille
D14: ways-of-reading-nonvisual-reading-not-fully | E14: Not fully readable in read aloud or dynamic braille
... D79: additional-accessibility-information-without-background-sounds | E79: Without background sounds
